2022-10-18 23:33:04,970 redisClient.py[line:149] ERROR redis connection error: Error 61 connecting to 127.0.0.1:6379. Connection refused.
Traceback (most recent call last):
  File "/Users/nofd/opt/anaconda3/lib/python3.9/site-packages/redis/connection.py", line 611, in connect
    sock = self.retry.call_with_retry(
  File "/Users/nofd/opt/anaconda3/lib/python3.9/site-packages/redis/retry.py", line 46, in call_with_retry
    return do()
  File "/Users/nofd/opt/anaconda3/lib/python3.9/site-packages/redis/connection.py", line 612, in <lambda>
    lambda: self._connect(), lambda error: self.disconnect(error)
  File "/Users/nofd/opt/anaconda3/lib/python3.9/site-packages/redis/connection.py", line 677, in _connect
    raise err
  File "/Users/nofd/opt/anaconda3/lib/python3.9/site-packages/redis/connection.py", line 665, in _connect
    sock.connect(socket_address)
ConnectionRefusedError: [Errno 61] Connection refused

During handling of the above exception, another exception occurred:

Traceback (most recent call last):
  File "/Volumes/Data/Documents/大三/毕设/爬虫/proxy_pool-2.4.0/db/redisClient.py", line 144, in test
    self.getCount()
  File "/Volumes/Data/Documents/大三/毕设/爬虫/proxy_pool-2.4.0/db/redisClient.py", line 130, in getCount
    proxies = self.getAll(https=False)
  File "/Volumes/Data/Documents/大三/毕设/爬虫/proxy_pool-2.4.0/db/redisClient.py", line 112, in getAll
    items = self.__conn.hvals(self.name)
  File "/Users/nofd/opt/anaconda3/lib/python3.9/site-packages/redis/commands/core.py", line 4887, in hvals
    return self.execute_command("HVALS", name)
  File "/Users/nofd/opt/anaconda3/lib/python3.9/site-packages/redis/client.py", line 1235, in execute_command
    conn = self.connection or pool.get_connection(command_name, **options)
  File "/Users/nofd/opt/anaconda3/lib/python3.9/site-packages/redis/connection.py", line 1582, in get_connection
    connection.connect()
  File "/Users/nofd/opt/anaconda3/lib/python3.9/site-packages/redis/connection.py", line 617, in connect
    raise ConnectionError(self._error_message(e))
redis.exceptions.ConnectionError: Error 61 connecting to 127.0.0.1:6379. Connection refused.
